Workbook

Sheet Financials of TCS
B2: Balance Sheet of Tata Consultancy Services | C2: 2020 | D2: 2021 | E2: 2022 | F2: 2023 | G2: 2024 | H2: 2025 | K2: Income Statement of Tata Consultancy Services | L2: 2020 | M2: 2021 | N2: 2022 | O2: 2023 | P2: 2024 | Q2: 2025 | S2: Cash Flow Statement of Tata Consultancy Services | T2: 2020 | U2: 2021 | V2: 2022 | W2: 2023 | X2: 2024 | Y2: 2025
B3: Equity Capital | C3: 375 | D3: 370 | E3: 366 | F3: 366 | G3: 362 | H3: 362 | K3: Sales - | L3: 156949 | M3: 164177 | N3: 191754 | O3: 225458 | P3: 240893 | Q3: 255324 | S3: Cash from Operating Activity - | T3: 32369 | U3: 38802 | V3: 39949 | W3: 41965 | X3: 44338 | Y3: 48908
B4: Reserves | C4: 83751 | D4: 86063 | E4: 88773 | F4: 90058 | G4: 90127 | H4: 94394 | K4: Sales Growth % | L4: 0.0716 | M4: 0.0461 | N4: 0.168 | O4: 0.1758 | P4: 0.0685 | Q4: 0.0599 | S4: Profit from operations | T4: 42882 | U4: 47031 | V4: 54204 | W4: 59148 | X4: 63709 | Y4: 67853
B5: Borrowings - | C5: 8174 | D5: 7795 | E5: 7818 | F5: 7688 | G5: 8021 | H5: 9392 | K5: Expenses - | L5: 114840 | M5: 117631 | N5: 138697 | O5: 166199 | P5: 176597 | Q5: 187917 | S5: Receivables | T5: -3295 | U5: 1059 | V5: -5144 | W5: -7683 | X5: -3332 | Y5: -5228
B6: Long term Borrowings | C6: 0 | D6: 0 | E6: 0 | F6: 0 | G6: 0 | H6: 0 | K6: Material Cost % + | L6: 0 | M6: 0 | N6: 0 | O6: 0 | P6: 0 | Q6: 0 | S6: Inventory | T6: 5 | U6: -3 | V6: -12 | W6: -8 | X6: 0 | Y6: 7
B7: Short term Borrowings | C7: 0 | D7: 0 | E7: 0 | F7: 0 | G7: 0 | H7: 0 | K7: Manufacturing Cost % | L7: 0.01 | M7: 0.01 | N7: 0.01 | O7: 0.01 | P7: 0.02 | Q7: 0.05 | S7: Payables | T7: 446 | U7: -93 | V7: 186 | W7: 2036 | X7: -632 | Y7: 3718
B8: Lease Liabilities | C8: 8174 | D8: 7795 | E8: 7818 | F8: 7688 | G8: 8021 | H8: 9392 | K8: Employee Cost % | L8: 0.55 | M8: 0.56 | N8: 0.56 | O8: 0.57 | P8: 0.58 | Q8: 0.57 | S8: Loans Advances | T8: 0 | U8: -17 | V8: -116 | W8: 261 | X8: -301 | Y8: -738
B9: Other Borrowings | C9: 0 | D9: 0 | E9: 0 | F9: 0 | G9: 0 | H9: 0 | K9: Other Cost % | L9: 0.17 | M9: 0.15 | N9: 0.16 | O9: 0.16 | P9: 0.14 | Q9: 0.12 | S9: Other WC items | T9: -1823 | U9: -83 | V9: 2317 | W9: 1177 | X9: -2617 | Y9: -1118
B10: Other Liabilities - | C10: 27827 | D10: 35764 | E10: 43967 | F10: 44747 | G10: 46962 | H10: 54501 | K10: Operating Profit | L10: 42109 | M10: 46546 | N10: 53057 | O10: 59259 | P10: 64296 | Q10: 67407 | S10: Working capital changes | T10: -4667 | U10: 863 | V10: -2769 | W10: -4217 | X10: -6882 | Y10: -3359
B11: Non controlling int | C11: 623 | D11: 675 | E11: 707 | F11: 782 | G11: 830 | H11: 1015 | K11: OPM % | L11: 0.27 | M11: 0.28 | N11: 0.28 | O11: 0.26 | P11: 0.27 | Q11: 0.26 | S11: Direct taxes | T11: -5846 | U11: -9092 | V11: -11486 | W11: -12966 | X11: -12489 | Y11: -15586
B12: Trade Payables | C12: 6740 | D12: 7860 | E12: 8045 | F12: 10515 | G12: 9981 | H12: 13909 | K12: Other Income - | L12: 4592 | M12: 1916 | N12: 4018 | O12: 3449 | P12: 3464 | Q12: 3962 | S12: Cash from Investing Activity - | T12: 8968 | U12: -7956 | V12: -738 | W12: 548 | X12: 6091 | Y12: -2144
B13: Advance from Customers | C13: 345 | D13: 312 | E13: 468 | F13: 543 | G13: 1841 | H13: 1896 | K13: Exceptional items | L13: 60 | M13: -1205 | N13: 23 | O13: 30 | P13: -933 | Q13: 46 | S13: Fixed assets purchased | T13: -3249 | U13: -3176 | V13: -2995 | W13: -3100 | X13: -2674 | Y13: -3937
... B27: Accumulated Depreciation | C27: 17056 | D27: 19430 | E27: 20243 | F27: 24899 | G27: 27814 | H27: 30313 | K27: Dividend Payout % | L27: 0.85 | M27: 0.43 | N27: 0.41 | O27: 1 | P27: 0.58 | Q27: 0.94 | S27: Dividends paid | T27: -37702 | U27: -10907 | V27: -13375 | W27: -41410 | X27: -25218 | Y27: -44962
B28: CWIP | C28: 906 | D28: 926 | E28: 1205 | F28: 1234 | G28: 1564 | H28: 1546 | S28: Financial liabilities | T28: -1062 | U28: -1336 | V28: -1417 | W28: -1515 | X28: -1614 | Y28: -1664
B29: Investments | C29: 26356 | D29: 29373 | E29: 30485 | F29: 37163 | G29: 31762 | H29: 30964 | S29: Other financing items | T29: -227 | U29: -19757 | V29: -18091 | W29: -4192 | X29: -21430 | Y29: 28
B30: Other Assets - | C30: 71937 | D30: 78672 | E30: 87936 | F30: 83947 | G30: 92542 | H30: 103086 | S30: Net Cash Flow | T30: 1422 | U30: -1788 | V30: 5630 | W30: -5365 | X30: 1893 | Y30: -674
B31: Inventories | C31: 5 | D31: 8 | E31: 20 | F31: 28 | G31: 28 | H31: 21 | S31: Free Cash Flow | T31: 29281 | U31: 35663 | V31: 36985 | W31: 38902 | X31: 41688 | Y31: 44994
B32: Trade receivables + | C32: 30532 | D32: 30079 | E32: 41810 | F32: 49954 | G32: 53577 | H32: 59046 | S32: CFO/OP | T32: 0.91 | U32: 1.03 | V32: 0.97 | W32: 0.93 | X32: 0.88 | Y32: 0.96
B33: Cash Equivalents | C33: 9666 | D33: 9329 | E33: 18221 | F33: 11032 | G33: 13286 | H33: 15463
B34: Loans n Advances | C34: 1967 | D34: 5107 | E34: 3600 | F34: 2097 | G34: 3989 | H34: 4612
B35: Other asset items | C35: 29767 | D35: 34149 | E35: 24285 | F35: 20836 | G35: 21662 | H35: 23944
B36: Total Assets | C36: 120127 | D36: 129992 | E36: 140924 | F36: 142859 | G36: 145472 | H36: 158649

Sheet Ratios
B2: Key Financial Ratios of Tata Consultancy Services(in Rs. Cr.) | C2: 45717 | D2: 45352 | E2: 44986 | F2: 44621 | G2: 44256 | I2: Key Financial Ratios of Infosys (in Rs. Cr.) | J2: 45717 | K2: 45352 | L2: 44986 | M2: 44621 | N2: 44256 | Q2: Key Financial Ratios of Tech Mahindra (in Rs. Cr.) | R2: 45717 | S2: 45352 | T2: 44986 | U2: 44621 | V2: 44256 | Y2: Key Financial Ratios of Wipro (in Rs. Cr.) | Z2: 45717 | AA2: 45352 | AB2: 44986 | AC2: 44621 | AD2: 44256 | AG2: KEY FINANCIAL RATIOS OF LTIMINDTREE (in Rs. Cr.) | AH2: 45717 | AI2: 45352 | AJ2: 44986 | AK2: 44621 | AL2: 44256 | AO2: KEY FINANCIAL RATIOS OF HCL TECHNOLOGIES (in Rs. Cr.) | AP2: 45717 | AQ2: 45352 | AR2: 44986 | AS2: 44621 | AT2: 44256
B3: PER SHARE RATIOS | I3: PER SHARE RATIOS | Q3: PER SHARE RATIOS | Y3: PER SHARE RATIOS | AG3: PER SHARE RATIOS | AO3: PER SHARE RATIOS
B4: Basic EPS (Rs.) | C4: 132.83 | D4: 119.44 | E4: 106.88 | F4: 103.24 | G4: 82.78 | I4: Basic EPS (Rs.) | J4: 61.58 | K4: 65.62 | L4: 55.48 | M4: 50.27 | N4: 42.37 | Q4: Basic EPS (Rs.) | R4: 35.78 | S4: 21.75 | T4: 38.69 | U4: 50.48 | V4: 43.76 | Y4: Basic EPS (Rs.) | Z4: 10.32 | AA4: 17.24 | AB4: 16.75 | AC4: 22.2 | AD4: 17.81 | AG4: Basic EPS (Rs.) | AH4: 155.29 | AI4: 154.85 | AJ4: 149.07 | AK4: 131.19 | AL4: 110.98 | AO4: Basic EPS (Rs.) | AP4: 64.16 | AQ4: 57.99 | AR4: 54.85 | AS4: 49.77 | AT4: 41.07
B5: Diluted EPS (Rs.) | C5: 132.83 | D5: 119.44 | E5: 106.88 | F5: 103.24 | G5: 82.78 | I5: Diluted EPS (Rs.) | J5: 61.46 | K5: 65.56 | L5: 55.42 | M5: 50.21 | N5: 42.33 | Q5: Diluted EPS (Rs.) | R5: 35.71 | S5: 21.69 | T5: 38.54 | U5: 50.11 | V5: 43.41 | Y5: Diluted EPS (Rs.) | Z5: 10.29 | AA5: 17.19 | AB5: 16.75 | AC5: 22.14 | AD5: 17.77 | AG5: Diluted EPS (Rs.) | AH5: 155 | AI5: 154.85 | AJ5: 148.83 | AK5: 130.81 | AL5: 110.26 | AO5: Diluted EPS (Rs.) | AP5: 64.09 | AQ5: 57.86 | AR5: 54.79 | AS5: 49.77 | AT5: 41.07
B6: Cash EPS (Rs.) | C6: 144.41 | D6: 131.07 | E6: 117.61 | F6: 113.96 | G6: 91.93 | I6: Cash EPS (Rs.) | J6: 67.89 | K6: 72.72 | L6: 62.73 | M6: 56.26 | N6: 47.81 | Q6: Cash EPS (Rs.) | R6: 44.55 | S6: 30.13 | T6: 47.12 | U6: 57.35 | V6: 50.62 | Y6: Cash EPS (Rs.) | Z6: 11.69 | AA6: 20.31 | AB6: 19.62 | AC6: 24.85 | AD6: 20.83 | AG6: Cash EPS (Rs.) | AH6: 188.97 | AI6: 182.55 | AJ6: 173.41 | AK6: 151.62 | AL6: 129.75 | AO6: Cash EPS (Rs.) | AP6: 79.13 | AQ6: 73.23 | AR6: 69.94 | AS6: 65.75 | AT6: 58.12
B7: Book Value [ExclRevalReserve]/Share (Rs.) | C7: 208.89 | D7: 199.23 | E7: 203.66 | F7: 210.86 | G7: 202.15 | I7: Book Value [ExclRevalReserve]/Share (Rs.) | J7: 210.34 | K7: 195.6 | L7: 163.32 | M7: 164.78 | N7: 167.91 | Q7: Book Value [ExclRevalReserve]/Share (Rs.) | R7: 229.02 | S7: 237.19 | T7: 254.79 | U7: 265.96 | V7: 258.32 | Y7: Book Value [ExclRevalReserve]/Share (Rs.) | Z7: 60.07 | AA7: 110.59 | AB7: 114.36 | AC7: 99.14 | AD7: 82.57 | AG7: Book Value [ExclRevalReserve]/Share (Rs.) | AH7: 766.83 | AI7: 676.56 | AJ7: 560.78 | AK7: 504.02 | AL7: 417.55 | AO7: Book Value [ExclRevalReserve]/Share (Rs.) | AP7: 256.56 | AQ7: 251.46 | AR7: 240.88 | AS7: 228.38 | AT7: 221.3
B8: Book Value [InclRevalReserve]/Share (Rs.) | C8: 208.89 | D8: 199.23 | E8: 203.66 | F8: 210.86 | G8: 202.15 | I8: Book Value [InclRevalReserve]/Share (Rs.) | J8: 210.34 | K8: 195.6 | L8: 163.32 | M8: 164.78 | N8: 167.91 | Q8: Book Value [InclRevalReserve]/Share (Rs.) | R8: 229.02 | S8: 237.19 | T8: 254.79 | U8: 265.96 | V8: 258.32 | Y8: Book Value [InclRevalReserve]/Share (Rs.) | Z8: 60.07 | AA8: 110.59 | AB8: 114.36 | AC8: 99.14 | AD8: 82.57 | AG8: Book Value [InclRevalReserve]/Share (Rs.) | AH8: 766.83 | AI8: 676.56 | AJ8: 560.78 | AK8: 504.02 | AL8: 417.55 | AO8: Book Value [InclRevalReserve]/Share (Rs.) | AP8: 256.56 | AQ8: 251.46 | AR8: 240.88 | AS8: 228.38 | AT8: 221.3
B9: Dividend / Share(Rs.) | C9: 126 | D9: 73 | E9: 115 | F9: 43 | G9: 38 | I9: Dividend / Share(Rs.) | J9: 43 | K9: 46 | L9: 34 | M9: 31 | N9: 27 | Q9: Dividend / Share(Rs.) | R9: 45 | S9: 40 | T9: 50 | U9: 45 | V9: 45 | Y9: Dividend / Share(Rs.) | Z9: 6 | AA9: 1 | AB9: 1 | AC9: 6 | AD9: 1 | AG9: Revenue from Operations/Share (Rs.) | AH9: 1284.06 | AI9: 1199.9 | AJ9: 1121.05 | AK9: 895.35 | AL9: 706.85 | AO9: Revenue from Operations/Share (Rs.) | AP9: 431.14 | AQ9: 404.84 | AR9: 373.69 | AS9: 315.47 | AT9: 277.64
B10: Revenue from Operations/Share (Rs.) | C10: 593.52 | D10: 559 | E10: 520.09 | F10: 438.09 | G10: 367.47 | I10: Revenue from Operations/Share (Rs.) | J10: 328.98 | K10: 310.68 | L10: 298.97 | M10: 247.12 | N10: 201.67 | Q10: Revenue from Operations/Share (Rs.) | R10: 455.74 | S10: 430.99 | T10: 437.87 | U10: 357.34 | V10: 306.14 | Y10: Revenue from Operations/Share (Rs.) | Z10: 64.26 | AA10: 127.83 | AB10: 123.46 | AC10: 108.67 | AD10: 91.8 | AG10: PBDIT/Share (Rs.) | AH10: 252.86 | AI10: 239.5 | AJ10: 225.16 | AK10: 201.43 | AL10: 171.4 | AO10: PBDIT/Share (Rs.) | AP10: 103.09 | AQ10: 94.63 | AR10: 88.35 | AS10: 79.55 | AT10: 77.26
B11: PBDIT/Share (Rs.) | C11: 186.66 | D11: 174.36 | E11: 153.89 | F11: 146.81 | G11: 123.54 | I11: PBDIT/Share (Rs.) | J11: 92.2 | K11: 94.4 | L11: 83.3 | M11: 73.83 | N11: 63.2 | Q11: PBDIT/Share (Rs.) | R11: 57.11 | S11: 37.12 | T11: 60.54 | U11: 72.11 | V11: 64.57 | Y11: PBDIT/Share (Rs.) | Z11: 16.1 | AA11: 28.19 | AB11: 26.4 | AC11: 31.22 | AD11: 26.35 | AG11: PBIT/Share (Rs.) | AH11: 219.36 | AI11: 211.84 | AJ11: 200.74 | AK11: 181.15 | AL11: 152.4 | AO11: PBIT/Share (Rs.) | AP11: 88.05 | AQ11: 79.26 | AR11: 73.08 | AS11: 63.61 | AT11: 60.27
B12: PBIT/Share (Rs.) | C12: 175 | D12: 163.63 | E12: 143.13 | F12: 137.18 | G12: 115.29 | I12: PBIT/Share (Rs.) | J12: 85.89 | K12: 87.3 | L12: 76.66 | M12: 68.05 | N12: 57.75 | Q12: PBIT/Share (Rs.) | R12: 48.37 | S12: 28.78 | T12: 52.2 | U12: 65.32 | V12: 57.73 | Y12: PBIT/Share (Rs.) | Z12: 14.72 | AA12: 25.33 | AB12: 23.5 | AC12: 28.51 | AD12: 23.89 | AG12: PBT/Share (Rs.) | AH12: 209.94 | AI12: 204.35 | AJ12: 195.66 | AK12: 176.99 | AL12: 147.9 | AO12: PBT/Share (Rs.) | AP12: 85.68 | AQ12: 77.23 | AR12: 71.78 | AS12: 62.44 | AT12: 58.39
B13: PBT/Share (Rs.) | C13: 173.06 | D13: 159.12 | E13: 141.23 | F13: 135.86 | G13: 110.55 | I13: PBT/Share (Rs.) | J13: 85.36 | K13: 86.63 | L13: 76.28 | M13: 67.75 | N13: 57.46 | Q13: PBT/Share (Rs.) | R13: 45.94 | S13: 26.26 | T13: 50.34 | U13: 64.67 | V13: 57.08 | Y13: PBT/Share (Rs.) | Z13: 13.78 | AA13: 23.77 | AB13: 22.36 | AC13: 27.84 | AD13: 23.15 | AG13: Net Profit/Share (Rs.) | AH13: 155.47 | AI13: 154.89 | AJ13: 149 | AK13: 131.34 | AL13: 110.75 | AO13: Net Profit/Share (Rs.) | AP13: 64.08 | AQ13: 57.86 | AR13: 54.68 | AS13: 49.81 | AT13: 41.14
B14: Net Profit/Share (Rs.) | C14: 132.75 | D14: 120.33 | E14: 106.85 | F14: 104.34 | G14: 83.68 | I14: Net Profit/Share (Rs.) | J14: 61.58 | K14: 65.62 | L14: 56.09 | M14: 50.49 | N14: 42.37 | Q14: Net Profit/Share (Rs.) | R14: 35.81 | S14: 21.79 | T14: 38.78 | U14: 50.56 | V14: 43.78 | Y14: Net Profit/Share (Rs.) | Z14: 10.31 | AA14: 17.45 | AB14: 16.72 | AC14: 22.14 | AD14: 18.36 | AG14: NP After MI And SOA / Share (Rs.) | AH14: 155.36 | AI14: 154.8 | AJ14: 148.93 | AK14: 131.25 | AL14: 110.63 | AO14: NP After MI And SOA / Share (Rs.) | AP14: 64.05 | AQ14: 57.83 | AR14: 54.7 | AS14: 49.72 | AT14: 41.05
B15: PROFITABILITY RATIOS | I15: PROFITABILITY RATIOS | Q15: PROFITABILITY RATIOS | Y15: PROFITABILITY RATIOS | AG15: PROFITABILITY RATIOS | AO15: PROFITABILITY RATIOS
B16: PBDIT Margin (%) | C16: 31.44 | D16: 31.19 | E16: 29.58 | F16: 33.51 | G16: 33.61 | I16: PBDIT Margin (%) | J16: 28.02 | K16: 30.38 | L16: 27.86 | M16: 29.87 | N16: 31.33 | Q16: PBDIT Margin (%) | R16: 12.53 | S16: 8.61 | T16: 13.82 | U16: 20.18 | V16: 21.09 | Y16: PBDIT Margin (%) | Z16: 25.05 | AA16: 22.05 | AB16: 21.38 | AC16: 28.73 | AD16: 28.7 | AG16: PBDIT Margin (%) | AH16: 19.69 | AI16: 19.96 | AJ16: 20.08 | AK16: 22.49 | AL16: 24.24 | AO16: PBDIT Margin (%) | AP16: 23.91 | AQ16: 23.37 | AR16: 23.64 | AS16: 25.21 | AT16: 27.82
B17: PBIT Margin (%) | C17: 29.48 | D17: 29.27 | E17: 27.51 | F17: 31.31 | G17: 31.37 | I17: PBIT Margin (%) | J17: 26.1 | K17: 28.09 | L17: 25.64 | M17: 27.53 | N17: 28.63 | Q17: PBIT Margin (%) | R17: 10.61 | S17: 6.67 | T17: 11.92 | U17: 18.28 | V17: 18.85 | Y17: PBIT Margin (%) | Z17: 22.9 | AA17: 19.81 | AB17: 19.03 | AC17: 26.23 | AD17: 26.01 | AG17: PBIT Margin (%) | AH17: 17.08 | AI17: 17.65 | AJ17: 17.9 | AK17: 20.23 | AL17: 21.56 | AO17: PBIT Margin (%) | AP17: 20.42 | AQ17: 19.57 | AR17: 19.55 | AS17: 20.16 | AT17: 21.7
B18: PBT Margin (%) | C18: 29.15 | D18: 28.46 | E18: 27.15 | F18: 31.01 | G18: 30.08 | I18: PBT Margin (%) | J18: 25.94 | K18: 27.88 | L18: 25.51 | M18: 27.41 | N18: 28.49 | Q18: PBT Margin (%) | R18: 10.07 | S18: 6.09 | T18: 11.49 | U18: 18.09 | V18: 18.64 | Y18: PBT Margin (%) | Z18: 21.44 | AA18: 18.59 | AB18: 18.1 | AC18: 25.62 | AD18: 25.21 | AG18: PBT Margin (%) | AH18: 16.34 | AI18: 17.03 | AJ18: 17.45 | AK18: 19.76 | AL18: 20.92 | AO18: PBT Margin (%) | AP18: 19.87 | AQ18: 19.07 | AR18: 19.2 | AS18: 19.79 | AT18: 21.03
B19: Net Profit Margin (%) | C19: 22.36 | D19: 21.52 | E19: 20.54 | F19: 23.81 | G19: 22.77 | I19: Net Profit Margin (%) | J19: 18.71 | K19: 21.12 | L19: 18.76 | M19: 20.43 | N19: 21 | Q19: Net Profit Margin (%) | R19: 7.85 | S19: 5.05 | T19: 8.85 | U19: 14.14 | V19: 14.3 | Y19: Net Profit Margin (%) | Z19: 16.03 | AA19: 13.65 | AB19: 13.54 | AC19: 20.36 | AD19: 20 | AG19: Net Profit Margin (%) | AH19: 12.1 | AI19: 12.9 | AJ19: 13.29 | AK19: 14.66 | AL19: 15.66 | AO19: Net Profit Margin (%) | AP19: 14.86 | AQ19: 14.29 | AR19: 14.63 | AS19: 15.78 | AT19: 14.81
B20: Return on Networth / Equity (%) | C20: 63.55 | D20: 60.39 | E20: 52.46 | F20: 49.48 | G20: 41.39 | I20: Return on Networth / Equity (%) | J20: 29.27 | K20: 33.54 | L20: 34.34 | M20: 30.63 | N20: 25.23 | Q20: Return on Networth / Equity (%) | R20: 15.63 | S20: 9.18 | T20: 15.21 | U20: 19 | V20: 16.94 | Y20: Return on Networth / Equity (%) | Z20: 17.15 | AA20: 15.78 | AB20: 14.62 | AC20: 22.32 | AD20: 22.23 | AG20: NP After MI And SOA Margin (%) | AH20: 12.09 | AI20: 12.9 | AJ20: 13.28 | AK20: 14.65 | AL20: 15.65 | AO20: NP After MI And SOA Margin (%) | AP20: 14.85 | AQ20: 14.28 | AR20: 14.63 | AS20: 15.76 | AT20: 14.78
B21: Return on Capital Employed (%) | C21: 75.77 | D21: 75.85 | E21: 65.07 | F21: 60.23 | G21: 52.75 | I21: Return on Capital Employed (%) | J21: 38.27 | K21: 41.23 | L21: 43.03 | M21: 38.46 | N21: 32.23 | Q21: Return on Capital Employed (%) | R21: 18.44 | S21: 10.88 | T21: 19.23 | U21: 22.37 | V21: 20.39 | Y21: Return on Capital Employed (%) | Z21: 22.15 | AA21: 20.94 | AB21: 19.4 | AC21: 27.32 | AD21: 27.49 | AG21: Return on Networth/Equity (%) | AH21: 20.26 | AI21: 22.89 | AJ21: 26.56 | AK21: 26.05 | AL21: 26.5 | AO21: Return on Networth/Equity (%) | AP21: 24.96 | AQ21: 23 | AR21: 22.7 | AS21: 21.8 | AT21: 18.6
B22: Return on Assets (%) | C22: 36.19 | D22: 35.95 | E22: 32.63 | F22: 31.49 | G22: 28.3 | I22: Return on Assets (%) | J22: 20.46 | K22: 23.69 | L22: 22.96 | M22: 21.36 | N22: 19.21 | Q22: Return on Assets (%) | R22: 9.69 | S22: 6.14 | T22: 10.48 | U22: 14.03 | V22: 12.7 | Y22: Return on Assets (%) | Z22: 11.72 | AA22: 11.16 | AB22: 10.75 | AC22: 15.09 | AD22: 15.3 | AG22: Return on Capital Employed (%) | AH22: 26.32 | AI22: 28.73 | AJ22: 32.98 | AK22: 33.19 | AL22: 33.02 | AO22: Return on Capital Employed (%) | AP22: 30.84 | AQ22: 27.92 | AR22: 27.56 | AS22: 24.58 | AT22: 23.78
B23: Total Debt/Equity (X) | C23: 0 | D23: 0 | E23: 0 | F23: 0 | G23: 0 | I23: Total Debt/Equity (X) | J23: 0 | K23: 0 | L23: 0 | M23: 0 | N23: 0 | Q23: Total Debt/Equity (X) | R23: 0 | S23: 0 | T23: 0 | U23: 0 | V23: 0 | Y23: Total Debt/Equity (X) | Z23: 0.1 | AA23: 0.07 | AB23: 0.08 | AC23: 0.14 | AD23: 0.13 | AG23: Return on Assets (%) | AH23: 15.01 | AI23: 16.62 | AJ23: 18.76 | AK23: 18.41 | AL23: 18.07 | AO23: Return on Assets (%) | AP23: 16.47 | AQ23: 15.73 | AR23: 15.89 | AS23: 15.16 | AT23: 12.93
B24: Asset Turnover Ratio (%) | C24: 1.69 | D24: 1.68 | E24: 1.58 | F24: 1.39 | G24: 1.27 | I24: Asset Turnover Ratio (%) | J24: 1.14 | K24: 1.19 | L24: 1.24 | M24: 1.08 | N24: 91.45 | Q24: Asset Turnover Ratio (%) | R24: 1.26 | S24: 1.19 | T24: 1.2 | U24: 1.02 | V24: 0.93 | Y24: Asset Turnover Ratio (%) | Z24: 0.77 | AA24: 0.8 | AB24: 0.82 | AC24: 0.82 | AD24: 0.77 | AG24: Total Debt/Equity (X) | AH24: 0 | AI24: 0 | AJ24: 0.01 | AK24: 0.09 | AL24: 0.01 | AO24: Total Debt/Equity (X) | AP24: 0.03 | AQ24: 0.03 | AR24: 0.03 | AS24: 0.06 | AT24: 0.06
B25: LIQUIDITY RATIOS | I25: LIQUIDITY RATIOS | Q25: LIQUIDITY RATIOS | Y25: LIQUIDITY RATIOS | AG25: Asset Turnover Ratio (%) | AH25: 1.31 | AI25: 1.39 | AJ25: 1.83 | AK25: 1.29 | AL25: 1.23 | AO25: Asset Turnover Ratio (%) | AP25: 1.14 | AQ25: 1.14 | AR25: 0.65 | AS25: 0.58 | AT25: 87.45
B26: Current Ratio (X) | C26: 2.1 | D26: 2.2 | E26: 2.36 | F26: 2.49 | G26: 2.92 | I26: Current Ratio (X) | J26: 2.43 | K26: 2.62 | L26: 1.9 | M26: 2.1 | N26: 2.74 | Q26: Current Ratio (X) | R26: 1.67 | S26: 1.9 | T26: 1.81 | U26: 2.56 | V26: 3.36 | Y26: Current Ratio (X) | Z26: 2.68 | AA26: 2.74 | AB26: 2.86 | AC26: 2.23 | AD26: 2.5 | AG26: LIQUIDITY RATIOS | AO26: LIQUIDITY RATIOS
B27: Quick Ratio (X) | C27: 2.1 | D27: 2.2 | E27: 2.36 | F27: 2.48 | G27: 2.92 | I27: Quick Ratio (X) | J27: 2.43 | K27: 2.62 | L27: 1.9 | M27: 2.1 | N27: 2.74 | Q27: Quick Ratio (X) | R27: 1.67 | S27: 1.9 | T27: 1.81 | U27: 2.56 | V27: 3.36 | Y27: Quick Ratio (X) | Z27: 2.68 | AA27: 2.74 | AB27: 2.86 | AC27: 2.23 | AD27: 2.5 | AG27: Current Ratio (X) | AH27: 3.51 | AI27: 3.28 | AJ27: 3.13 | AK27: 3.04 | AL27: 3.09 | AO27: Current Ratio (X) | AP27: 2.22 | AQ27: 2.61 | AR27: 2.5 | AS27: 2.56 | AT27: 2.48
B28: Inventory Turnover Ratio (X) | C28: 9142.68 | D28: 0 | E28: 0 | F28: 0 | G28: 0 | I28: Inventory Turnover Ratio (X) | J28: 0 | K28: 0 | L28: 0 | M28: 0 | N28: 0 | Q28: Inventory Turnover Ratio (X) | R28: 0 | S28: 0 | T28: 0 | U28: 0 | V28: 0 | Y28: Inventory Turnover Ratio (X) | Z28: 996.19 | AA28: 813.55 | AB28: 0 | AC28: 0 | AD28: 0 | AG28: Quick Ratio (X) | AH28: 3.51 | AI28: 3.28 | AJ28: 3.13 | AK28: 3.04 | AL28: 3.09 | AO28: Quick Ratio (X) | AP28: 2.21 | AQ28: 2.6 | AR28: 2.49 | AS28: 2.55 | AT28: 2.47
B29: Dividend Payout Ratio (NP) (%) | C29: 93.35 | D29: 57.7 | E29: 105.73 | F29: 34.87 | G29: 35.04 | I29: Dividend Payout Ratio (NP) (%) | J29: 79.57 | K29: 54.09 | L29: 58.77 | M29: 59.8 | N29: 50.74 | Q29: Dividend Payout Ratio (NP) (%) | R29: 119.97 | S29: 201.55 | T29: 123.63 | U29: 88.79 | V29: 45.61 | Y29: Dividend Payout Ratio (NP) (%) | Z29: 58.2 | AA29: 5.72 | AB29: 5.97 | AC29: 27.1 | AD29: 5.44 | AG29: Inventory Turnover Ratio (X) | AH29: 13106.24 | AI29: 0 | AJ29: 0 | AK29: 0 | AL29: 0 | AO29: Inventory Turnover Ratio (X) | AP29: 736.19 | AQ29: 0 | AR29: 0 | AS29: 0 | AT29: 801.9
B30: Dividend Payout Ratio (CP) (%) | C30: 85.81 | D30: 52.98 | E30: 96.05 | F30: 31.92 | G30: 31.89 | I30: Dividend Payout Ratio (CP) (%) | J30: 72.17 | K30: 48.82 | L30: 52.55 | M30: 53.66 | N30: 44.96 | Q30: Dividend Payout Ratio (CP) (%) | R30: 96.45 | S30: 145.75 | T30: 101.74 | U30: 78.27 | V30: 39.44 | Y30: Dividend Payout Ratio (CP) (%) | Z30: 51.32 | AA30: 4.92 | AB30: 5.09 | AC30: 24.14 | AD30: 4.8 | AG30: Dividend Payout Ratio (NP) (%) | AH30: 41.85 | AI30: 38.74 | AJ30: 35.44 | AK30: 38.09 | AL30: 27.49 | AO30: Dividend Payout Ratio (NP) (%) | AP30: 93.46 | AQ30: 89.67 | AR30: 87.5 | AS30: 84.38 | AT30: 29.22
B31: Earnings Retention Ratio (%) | C31: 6.65 | D31: 42.3 | E31: -5.73 | F31: 65.13 | G31: 64.96 | I31: Earnings Retention Ratio (%) | J31: 20.43 | K31: 45.91 | L31: 41.23 | M31: 40.2 | N31: 49.26 | Q31: Earnings Retention Ratio (%) | R31: -19.97 | S31: -101.55 | T31: -23.63 | U31: 11.21 | V31: 54.39 | Y31: Earnings Retention Ratio (%) | Z31: 41.8 | AA31: 94.28 | AB31: 94.03 | AC31: 72.9 | AD31: 94.56 | AG31: Dividend Payout Ratio (CP) (%) | AH31: 34.42 | AI31: 32.86 | AJ31: 30.45 | AK31: 32.99 | AL31: 23.46 | AO31: Dividend Payout Ratio (CP) (%) | AP31: 75.69 | AQ31: 70.84 | AR31: 68.4 | AS31: 63.9 | AT31: 20.67
B32: Cash Earnings Retention Ratio (%) | C32: 14.19 | D32: 47.02 | E32: 3.95 | F32: 68.08 | G32: 68.11 | I32: Cash Earnings Retention Ratio (%) | J32: 27.83 | K32: 51.18 | L32: 47.45 | M32: 46.34 | N32: 55.04 | Q32: Cash Earnings Retention Ratio (%) | R32: 3.55 | S32: -45.75 | T32: -1.74 | U32: 21.73 | V32: 60.56 | Y32: Cash Earnings Retention Ratio (%) | Z32: 48.68 | AA32: 95.08 | AB32: 94.91 | AC32: 75.86 | AD32: 95.2 | AG32: Earnings Retention Ratio (%) | AH32: 58.15 | AI32: 61.26 | AJ32: 64.56 | AK32: 61.91 | AL32: 72.51 | AO32: Earnings Retention Ratio (%) | AP32: 6.54 | AQ32: 10.33 | AR32: 12.5 | AS32: 15.62 | AT32: 70.78
B33: VALUATION RATIOS | I33: VALUATION RATIOS | Q33: VALUATION RATIOS | Y33: VALUATION RATIOS | AG33: Cash Earnings Retention Ratio (%) | AH33: 65.58 | AI33: 67.14 | AJ33: 69.55 | AK33: 67.01 | AL33: 76.54 | AO33: Cash Earnings Retention Ratio (%) | AP33: 24.31 | AQ33: 29.16 | AR33: 31.6 | AS33: 36.1 | AT33: 79.33
B34: Enterprise Value (Cr.) | C34: 1297658.9 | D34: 1399246.1 | E34: 1168779.8 | F34: 1354708.8 | G34: 1172570 | I34: Enterprise Value (Cr.) | J34: 637765.08 | K34: 613811 | L34: 585675.96 | M34: 789898.32 | N34: 565049.5 | Q34: Enterprise Value (Cr.) | R34: 137144.7 | S34: 120617.27 | T34: 106138.43 | U34: 144395.17 | V34: 94922.73 | Y34: Enterprise Value (Cr.) | Z34: 276213.72 | AA34: 251210.53 | AB34: 201130.34 | AC34: 327315.4 | AD34: 222962.28 | AG34: COVERAGE RATIOS | AO34: COVERAGE RATIOS
B35: EV/Net Operating Revenue (X) | C35: 6.04 | D35: 6.91 | E35: 6.14 | F35: 8.45 | G35: 8.62 | I35: EV/Net Operating Revenue (X) | J35: 4.67 | K35: 4.76 | L35: 4.72 | M35: 7.6 | N35: 6.58 | Q35: EV/Net Operating Revenue (X) | R35: 3.07 | S35: 2.87 | T35: 2.49 | U35: 4.16 | V35: 3.2 | Y35: EV/Net Operating Revenue (X) | Z35: 4.1 | AA35: 3.76 | AB35: 2.97 | AC35: 5.49 | AD35: 4.43 | AG35: Interest Coverage Ratios (%) | AH35: 26.84 | AI35: 31.98 | AJ35: 44.31 | AK35: 48.42 | AL35: 38.06 | AO35: Interest Coverage Ratios (%) | AP35: 43.46 | AQ35: 46.46 | AR35: 67.95 | AS35: 67.7 | AT35: 32.02
B36: EV/EBITDA (X) | C36: 19.2 | D36: 22.17 | E36: 20.75 | F36: 25.21 | G36: 25.65 | I36: EV/EBITDA (X) | J36: 16.66 | K36: 15.67 | L36: 16.95 | M36: 25.44 | N36: 20.99 | Q36: EV/EBITDA (X) | R36: 24.53 | S36: 33.26 | T36: 18 | U36: 20.6 | V36: 15.18 | Y36: EV/EBITDA (X) | Z36: 16.38 | AA36: 17.06 | AB36: 13.88 | AC36: 19.12 | AD36: 15.44 | AG36: Interest Coverage Ratios (Post Tax) (%) | AH36: 26.84 | AI36: 31.98 | AJ36: 44.31 | AK36: 48.42 | AL36: 38.06 | AO36: Interest Coverage Ratios (Post Tax) (%) | AP36: 43.46 | AQ36: 46.46 | AR36: 67.95 | AS36: 67.7 | AT36: 32.02
B37: MarketCap/Net Operating Revenue (X) | C37: 6.07 | D37: 6.95 | E37: 6.16 | F37: 8.53 | G37: 8.65 | I37: MarketCap/Net Operating Revenue (X) | J37: 4.77 | K37: 4.82 | L37: 4.78 | M37: 7.72 | N37: 6.78 | Q37: MarketCap/Net Operating Revenue (X) | R37: 3.11 | S37: 2.9 | T37: 2.52 | U37: 4.2 | V37: 3.24 | Y37: MarketCap/Net Operating Revenue (X) | Z37: 4.08 | AA37: 3.76 | AB37: 2.96 | AC37: 5.45 | AD37: 4.51 | AG37: VALUATION RATIOS | AO37: VALUATION RATIOS
B38: Retention Ratios (%) | C38: 6.64 | D38: 42.29 | E38: -5.73 | F38: 65.12 | G38: 64.95 | I38: Retention Ratios (%) | J38: 20.42 | K38: 45.9 | L38: 41.22 | M38: 40.19 | N38: 49.25 | Q38: Retention Ratios (%) | R38: -19.97 | S38: -101.55 | T38: -23.63 | U38: 11.2 | V38: 54.38 | Y38: Retention Ratios (%) | Z38: 41.79 | AA38: 94.27 | AB38: 94.02 | AC38: 72.89 | AD38: 94.55 | AG38: Enterprise Value (Cr.) | AH38: 129402.34 | AI38: 143343.94 | AJ38: 138037.2 | AK38: 107811.4 | AL38: 70125.7 | AO38: Enterprise Value (Cr.) | AP38: 412962.93 | AQ38: 401190.95 | AR38: 282423.3 | AS38: 307290.53 | AT38: 262115.68
B39: Price/BV (X) | C39: 17.26 | D39: 19.49 | E39: 15.74 | F39: 17.73 | G39: 15.72 | I39: Price/BV (X) | J39: 7.47 | K39: 7.66 | L39: 8.74 | M39: 11.57 | N39: 8.15 | Q39: Price/BV (X) | R39: 6.19 | S39: 5.27 | T39: 4.32 | U39: 5.64 | V39: 3.84 | Y39: Price/BV (X) | Z39: 4.36 | AA39: 4.34 | AB39: 3.19 | AC39: 5.97 | AD39: 5.02 | AG39: EV/Net Operating Revenue (X) | AH39: 3.4 | AI39: 4.04 | AJ39: 4.16 | AK39: 6.88 | AL39: 5.67 | AO39: EV/Net Operating Revenue (X) | AP39: 3.53 | AQ39: 3.65 | AR39: 2.78 | AS39: 3.59 | AT39: 3.48
B40: Price/Net Operating Revenue | C40: 6.07 | D40: 6.95 | E40: 6.16 | F40: 8.53 | G40: 8.65 | I40: Price/Net Operating Revenue | J40: 4.77 | K40: 4.82 | L40: 4.78 | M40: 7.72 | N40: 6.78 | Q40: Price/Net Operating Revenue | R40: 3.11 | S40: 2.9 | T40: 2.52 | U40: 4.2 | V40: 3.24 | Y40: Price/Net Operating Revenue | Z40: 4.08 | AA40: 3.76 | AB40: 2.96 | AC40: 5.45 | AD40: 4.51 | AG40: EV/EBITDA (X) | AH40: 17.29 | AI40: 20.22 | AJ40: 20.71 | AK40: 30.58 | AL40: 23.38 | AO40: EV/EBITDA (X) | AP40: 14.75 | AQ40: 15.61 | AR40: 11.77 | AS40: 14.23 | AT40: 12.5
B41: Earnings Yield | C41: 0.04 | D41: 0.03 | E41: 0.03 | F41: 0.03 | G41: 0.03 | I41: Earnings Yield | J41: 0.04 | K41: 0.04 | L41: 0.04 | M41: 0.03 | N41: 0.03 | Q41: Earnings Yield | R41: 0.03 | S41: 0.02 | T41: 0.04 | U41: 0.03 | V41: 0.04 | Y41: Earnings Yield | Z41: 0.04 | AA41: 0.04 | AB41: 0.05 | AC41: 0.04 | AD41: 0.04 | AG41: MarketCap/Net Operating Revenue (X) | AH41: 3.5 | AI41: 4.11 | AJ41: 4.24 | AK41: 6.88 | AL41: 5.73 | AO41: MarketCap/Net Operating Revenue (X) | AP41: 3.69 | AQ41: 3.81 | AR41: 2.91 | AS41: 3.69 | AT41: 3.54
...

Sheet Peer Comparison
B3: Tata Consultancy Services Vs. Peers | J3: Efficiency / Working Capital
B4: Ratio / Metric (in Rs. Cr) | C4: TCS | D4: Infosys | E4: Wipro | F4: Tech Mahindra | G4: HCL Tech | H4: LTI MindTree | J4: Ratio | K4: TCS | L4: Infosys | M4: Wipro | N4: Tech Mahindra | O4: HCL Tech | P4: LTI Mindtree
B5: Market Cap | C5: 872248 | D5: 517371 | E5: 200716 | F5: 137589 | G5: 367538 | H5: 121769 | J5: Debtor Days (DSO) | K5: 84 | L5: 69 | M5: 57 | N5: 76 | O5: 85.46 | P5: 71
B6: Enterprise Value (EV) | C6: =Ratios!C34 -> 1297658.9 | D6: =Ratios!J34 -> 637765.08 | E6: =Ratios!Z34 -> 276213.72 | F6: =Ratios!R34 -> 137144.7 | G6: 412962.93 | H6: 130010.34 | J6: Payable Days (DPO) | K6: 30 | L6: 14 | M6: 11 | N6: 38.5 | O6: 14 | P6: 15
B7: Revenue | C7: ='Financials of TCS'!Q3 -> 255324 | D7: 162990 | E7: 23555 | F7: 52988 | G7: 119540 | H7: 38008.1 | J7: Net Working Capital Days | K7: =K5-K6 -> 54 | L7: =L5-L6 -> 55 | M7: =M5-M6 -> 46 | N7: =N5-N6 -> 37.5 | O7: =O5-O6 -> 71.46 | P7: =P5-P6 -> 56
B8: EBIT | C8: ='Financials of TCS'!Q17-'Financials of TCS'!Q15 -> 64535 | D8: 38024 | E8: 18947 | F8: 5966 | G8: 23261 | H8: 6214.2 | J8: Asset Turnover | K8: 1.71x | L8: 1.14x | M8: 0.73x | N8: 1.25x | O8: 1.17x | P8: 1.63x
B9: EBITDA | C9: ='Financials of TCS'!Q10 -> 67407 | D9: =35441+2619 -> 38060 | E9: =14430.2+1446.6 -> 15876.8 | F9: =5966+855.2 -> 6821.2 | G9: =G8+4084 -> 27345 | H9: =H8+991.5 -> 7205.7
B10: Net Profit | C10: ='Financials of TCS'!Q19 -> 48797 | D10: 26750 | E10: 13192 | F10: 4244 | G10: 17399 | H10: 4598.7
B11: Stock price as on 30th March,2026 | C11: 2434 | D11: 1266.82 | E11: 195.23 | F11: 1432.97 | G11: 1347.85 | H11: 4297.8
B15: Valuation Multiples | J15: Profitability
B16: Multiple | C16: TCS | D16: Infosys | E16: Wipro | F16: Tech Mahindra | G16: HCL Tech | H16: LTI Mindtree | J16: Ratio | K16: TCS | L16: Infosys | M16: Wipro | N16: Tech Mahindra | O16: HCL Tech | P16: LTI Mindtree
B17: P / E | C17: =C11/Ratios!C4 -> 18.324174 | D17: =D11/Ratios!J4 -> 20.571939 | E17: =E11/Ratios!Z4 -> 18.917636 | F17: =F11/Ratios!R4 -> 40.049469 | G17: =G11/45.25 -> 29.78674 | H17: =H11/155 -> 27.727742 | J17: Gross Margin | K17: =Ratios!C16/100 -> 0.3144 | L17: =Ratios!J16/100 -> 0.2802 | M17: =Ratios!Z16/100 -> 0.2505 | N17: =Ratios!R16/100 -> 0.1253 | O17: =(23261+4084+644+7606)/G7 -> 0.29776644 | P17: =(6214.2+4259.4+991.5+278.9)/H7 -> 0.30898677
B18: EV / EBIT | C18: =C6/C8 -> 20.107831 | D18: =D6/D8 -> 16.772698 | E18: =E6/E8 -> 14.57823 | F18: =F6/F8 -> 22.987714 | G18: =G6/G8 -> 17.753447 | H18: =H6/H8 -> 20.921493 | J18: Operating Margin (EBIT) | K18: =Ratios!C17/100 -> 0.2948 | L18: =Ratios!J17/100 -> 0.261 | M18: =Ratios!Z17/100 -> 0.229 | N18: =Ratios!R17/100 -> 0.1061 | O18: =G8/G7 -> 0.19458759 | P18: =H8/H7 -> 0.16349673
B19: EV / EBITDA | C19: =C6/C9 -> 19.2511 | D19: =D6/D9 -> 16.756833 | E19: =E6/E9 -> 17.397317 | F19: =F6/F9 -> 20.105656 | G19: =G6/G9 -> 15.101954 | H19: =H6/H9 -> 18.042708 | J19: Net Profit Margin | K19: =Ratios!C19/100 -> 0.2236 | L19: =Ratios!J19/100 -> 0.1871 | M19: =Ratios!Z19/100 -> 0.1603 | N19: =Ratios!R19/100 -> 0.0785 | O19: =G10/G7 -> 0.14554961 | P19: =H10/H7 -> 0.12099263
B20: P / Sales | C20: =C5/C7 -> 3.4162398 | D20: =D5/D7 -> 3.17425 | E20: =E5/E7 -> 8.5211632 | F20: =F5/F7 -> 2.5966068 | G20: =G5/G7 -> 3.0746026 | H20: =H5/H7 -> 3.2037645 | J20: ROE | K20: =Ratios!C20/100 -> 0.6355 | L20: =Ratios!J20/100 -> 0.2927 | M20: =Ratios!Z20/100 -> 0.1715 | N20: =Ratios!R20/100 -> 0.1563 | O20: 0.2496 | P20: 0.2026
B21: EV / Sales | C21: =C6/C7 -> 5.0824008 | D21: =D6/D7 -> 3.9129093 | E21: =E6/E7 -> 11.726331 | F21: =F6/F7 -> 2.5882219 | G21: =G6/G7 -> 3.4546004 | H21: =H6/H7 -> 3.4205956 | J21: ROCE | K21: =Ratios!C21/100 -> 0.7577 | L21: =Ratios!J21/100 -> 0.3827 | M21: =Ratios!Z21/100 -> 0.2215 | N21: =Ratios!R21/100 -> 0.1844 | O21: 0.3084 | P21: 0.2632
J22: ROA | K22: =Ratios!C22/100 -> 0.3619 | L22: =Ratios!J22/100 -> 0.2046 | M22: =Ratios!Z22/100 -> 0.1172 | N22: =Ratios!R22/100 -> 0.0969 | O22: 0.1647 | P22: 0.1501
B26: Cash Flow Quality | J26: Leverage & Liquidity
B27: Ratio | C27: TCS | D27: Infosys | E27: Wipro | F27: Tech Mahindra | G27: HCL Tech | H27: LTI Mindtree | J27: Ratio | K27: TCS | L27: Infosys | M27: Wipro | N27: Tech Mahindra | O27: HCL Tech | P27: LTI Mindtree
B28: CFO / Net Profit | C28: ='Financials of TCS'!Y3/'Peer Comparison'!C10 -> 1.0022747 | D28: =35694/D10 -> 1.3343551 | E28: =16942/E10 -> 1.2842632 | F28: =4293.1/F10 -> 1.0115693 | G28: =22261/G9 -> 0.81407936 | H28: =3596.2/H9 -> 0.49907712 | J28: Debt / Equity | K28: 0.1x | L28: 0 | M28: 0.1x | N28: 0.02x | O28: 0.10x | P28: 0
B29: Free Cash Flow / Net Profit | C29: 0.97 | D29: =32030/D10 -> 1.1973832 | E29: =13740/E10 -> 1.0415403 | F29: =5653/F10 -> 1.3319981 | G29: =21260/G10 -> 1.2219093 | H29: =3596.2/H10 -> 0.78200361 | J29: Current Ratio | K29: 2.1x | L29: 2.43x | M29: 2.18x | N29: 1.87x | O29: 2.07x | P29: 3.60x
B30: Capex / Revenue | C30: 0.004 | D30: 0.01 | E30: 0.02 | F30: 0.01 | G30: 0.02 | H30: =3596.2/H11 -> 0.83675369 | J30: Interest Coverage | K30: 91.8x | L30: 91.4x | M30: 12.9x | N30: 18.6x | O30: 36.12x | P30: 22.28x
J32: These IT Services companies operates with negligible leverage, reflected in a near- zero D/E ratio.
J92: EBIT(tcs) | K92: ='Financials of TCS'!L17-'Financials of TCS'!L15 -> 41324

Sheet FCFF
B3: Unlevered Free Cash Flow (in Rs. Cr.)
B4: Fiscal Year | C4: 2021 | D4: 2022 | E4: 2023 | F4: 2024 | G4: 2025 | H4: 2026E | I4: 2027E | J4: 2028E | K4: 2029E | L4: 2030E
B5: Revenue | C5: 164177 | D5: ='Financials of TCS'!N3 -> 191754 | E5: ='Financials of TCS'!O3 -> 225458 | F5: ='Financials of TCS'!P3 -> 240893 | G5: ='Financials of TCS'!Q3 -> 255324 | H5: =G5*(1+H24) -> 271920.06 | I5: =H5*(1+I24) -> 290954.46 | J5: =I5*(1+J24) -> 312776.05 | K5: =J5*(1+K24) -> 337798.13 | L5: =K5*(1+L24) -> 364821.98
B6: Cost of Services | C6: ='Financials of TCS'!M5*85% -> 99986.35 | D6: ='Financials of TCS'!N5*84% -> 116505.48 | E6: ='Financials of TCS'!O5*84% -> 139607.16 | F6: ='Financials of TCS'!P5*86% -> 151873.42 | G6: ='Financials of TCS'!Q5*88% -> 165366.96 | H6: =H5*H26 -> 169348.78 | I6: =I5*I26 -> 181203.2 | J6: =J5*J26 -> 194793.44 | K6: =K5*K26 -> 210376.91 | L6: =L5*L26 -> 227207.06
B7: Gross Profit | C7: =C5-C6 -> 64190.65 | D7: =D5-D6 -> 75248.52 | E7: =E5-E6 -> 85850.84 | F7: =F5-F6 -> 89019.58 | G7: =G5-G6 -> 89957.04 | H7: =H5-H6 -> 102571.28 | I7: =I5-I6 -> 109751.27 | J7: =J5-J6 -> 117982.61 | ... L7: =L5-L6 -> 137614.92
B8: Operating Expenses(SG&A) | C8: ='Financials of TCS'!L5*'Financials of TCS'!L9 -> 19522.8 | D8: ='Financials of TCS'!M5*'Financials of TCS'!M9 -> 17644.65 | E8: ='Financials of TCS'!N5*'Financials of TCS'!N9 -> 22191.52 | F8: ='Financials of TCS'!O5*'Financials of TCS'!O9 -> 26591.84 | G8: ='Financials of TCS'!P5*'Financials of TCS'!P9 -> 24723.58 | H8: =H5*H27 -> 28093.673 | I8: =I5*I27 -> 30060.23 | J8: =J5*J27 -> 32314.748 | K8: =K5*K27 -> 34899.927 | L8: =L5*L27 -> 37691.922
B9: EBITDA | C9: =C7-C8 -> 44667.85 | D9: =D7-D8 -> 57603.87 | E9: =E7-E8 -> 63659.32 | F9: =F7-F8 -> 62427.74 | G9: =G7-G8 -> 65233.46 | H9: =H7-H8 -> 74477.605 | I9: =I7-I8 -> 79691.037 | J9: =J7-J8 -> 85667.865 | ... L9: =L7-L8 -> 99922.997
B10: Depreciation & Amortization | C10: 4065 | D10: 4604 | E10: 5022 | F10: 4985 | G10: 5242 | H10: ='Fixed Assets'!I6 -> 3096.7814 | I10: ='Fixed Assets'!J6 -> 2810.6748 | J10: ='Fixed Assets'!K6 -> 2551.0012 | K10: ='Fixed Assets'!L6 -> 2315.3184 | L10: ='Fixed Assets'!M6 -> 2101.4099
B11: Operating Profit (EBIT) | C11: =C9-C10 -> 40602.85 | D11: =D9-D10 -> 52999.87 | E11: =E9-E10 -> 58637.32 | F11: =F9-F10 -> 57442.74 | G11: =G9-G10 -> 59991.46 | H11: =H9-H10 -> 71380.823 | I11: =I9-I10 -> 76880.362 | J11: =J9-J10 -> 83116.864 | ... L11: =L9-L10 -> 97821.588
B12: Operating Taxes | C12: 11635 | D12: 13654 | E12: 14757 | F12: 15864 | G12: 16910 | H12: =H11*H28 -> 21414.247 | I12: =I11*I28 -> 23064.109 | J12: =J11*J28 -> 24935.059 | K12: =K11*K28 -> 27061.793 | L12: =L11*L28 -> 29346.476
B13: NOPAT (Net Operating Profit After Taxes) | C13: =C11-C12 -> 28967.85 | D13: =D11-D12 -> 39345.87 | E13: =E11-E12 -> 43880.32 | F13: =F11-F12 -> 41578.74 | G13: =G11-G12 -> 43081.46 | H13: =H11-H12 -> 49966.576 | I13: =I11-I12 -> 53816.254 | J13: =J11-J12 -> 58181.805 | ... L13: =L11-L12 -> 68475.111
B14: (+) Depreciation & Amortization | C14: =C10 -> 4065 | D14: =D10 -> 4604 | E14: =E10 -> 5022 | F14: =F10 -> 4985 | G14: =G10 -> 5242 | H14: =H10 -> 3096.7814 | I14: =I10 -> 2810.6748 | J14: =J10 -> 2551.0012 | ... L14: =L10 -> 2101.4099
B15: (-) Capital Expenditures | C15: =2719+101+356 -> 3176 | D15: 2995 | E15: 3100 | F15: 2674 | G15: 3937 | H15: ='Fixed Assets'!I7 -> 2142.0401 | I15: ='Fixed Assets'!J7 -> 1944.1405 | J15: ='Fixed Assets'!K7 -> 1764.5245 | K15: ='Fixed Assets'!L7 -> 1601.503 | L15: ='Fixed Assets'!M7 -> 1453.5428
B16: (-) Change in NWC | C16: =C17-23026 -> -535 | D16: =D17-C17 -> 10046 | E16: =E17-D17 -> 8594 | F16: =F17-E17 -> -428 | G16: =G17-F17 -> 3434 | H16: =H17-G17 -> 3318.7216 | I16: =I17-H17 -> 2052.8797 | J16: =J17-I17 -> 4022.4804 | K16: =K17-J17 -> 4743.9045 | L16: =L17-K17 -> 4824.8227
B17: NWC | C17: =C18-C19 -> 22491 | D17: =D18-D19 -> 32537 | E17: =E18-E19 -> 41131 | F17: =F18-F19 -> 40703 | G17: =G18-G19 -> 44137 | H17: =H18-H19 -> 47455.722 | I17: =I18-I19 -> 49508.601 | J17: =J18-J19 -> 53531.082 | ... L17: =L18-L19 -> 63099.809
B18: Current Assets | C18: ='Net Working Capital'!E9 -> 42551 | D18: ='Net Working Capital'!F9 -> 52609 | E18: ='Net Working Capital'!G9 -> 60381 | F18: ='Net Working Capital'!H9 -> 66608 | G18: ='Net Working Capital'!I9 -> 74718 | H18: ='Net Working Capital'!J9 -> 74854.032 | I18: ='Net Working Capital'!K9 -> 78824.793 | J18: ='Net Working Capital'!L9 -> 85045.988 | ... L18: ='Net Working Capital'!N9 -> 99858.795
B19: Current Liabilitites | C19: ='Net Working Capital'!E14 -> 20060 | D19: ='Net Working Capital'!F14 -> 20072 | E19: ='Net Working Capital'!G14 -> 19250 | F19: ='Net Working Capital'!H14 -> 25905 | G19: ='Net Working Capital'!I14 -> 30581 | H19: ='Net Working Capital'!J14 -> 27398.31 | I19: ='Net Working Capital'!K14 -> 29316.192 | J19: ='Net Working Capital'!L14 -> 31514.906 | ... L19: ='Net Working Capital'!N14 -> 36758.987
B20: Unlevered Free Cash Flow | C20: =C13+C14-C15-C16 -> 30391.85 | D20: =D13+D14-D15-D16 -> 30908.87 | E20: =E13+E14-E15-E16 -> 37208.32 | F20: =F13+F14-F15-F16 -> 44317.74 | G20: =G13+G14-G15-G16 -> 40952.46 | H20: =H13+H14-H15-H16 -> 47602.596 | I20: =I13+I14-I15-I16 -> 52629.908 | J20: =J13+J14-J15-J16 -> 54945.801 | ... L20: =L13+L14-L15-L16 -> 64298.156
B22: Assumptions
B23: Fiscal Year
B24: Revenue Growth | C24: =(C5/F98)-1 -> 0.046053177 | D24: =(D5/C5)-1 -> 0.16797115 | E24: =(E5/D5)-1 -> 0.17576687 | F24: =(F5/E5)-1 -> 0.068460645 | G24: =(G5/F5)-1 -> 0.059906265 | H24: 0.065 | I24: 0.07 | J24: 0.075 | K24: 0.08 | L24: 0.08
B26: COS % of Revenue | C26: =C6/C5 -> 0.60901557 | D26: =D6/D5 -> 0.60757783 | E26: =E6/E5 -> 0.61921582 | F26: =F6/F5 -> 0.63046008 | G26: =G6/G5 -> 0.64767495 | H26: =AVERAGE(C26:G26) -> 0.62278885 | I26: =H26 -> 0.62278885 | J26: =I26 -> 0.62278885 | K26: =J26 -> 0.62278885 | L26: =K26 -> 0.62278885
B27: SG&A % of Revenue | C27: =C8/C5 -> 0.11891312 | D27: =D8/D5 -> 0.092017116 | E27: =E8/E5 -> 0.098428621 | F27: =F8/F5 -> 0.1103886 | G27: =G8/G5 -> 0.096832182 | H27: =AVERAGE(C27:G27) -> 0.10331593 | I27: =H27 -> 0.10331593 | J27: =I27 -> 0.10331593 | K27: =J27 -> 0.10331593 | L27: =K27 -> 0.10331593
B28: Tax % of EBIT | C28: =C12/C11 -> 0.28655624 | D28: =D12/D11 -> 0.25762327 | E28: =E12/E11 -> 0.25166566 | F28: =F12/F11 -> 0.27617067 | G28: =G12/G11 -> 0.28187345 | H28: 0.3 | I28: =H28 -> 0.3 | J28: =I28 -> 0.3 | K28: =J28 -> 0.3 | L28: =K28 -> 0.3
E97: 2020 | F97: REVENUE | G97: COGS
F98: 156949 | G98: =119293-924 -> 118369

Sheet Fixed Assets
B3: Fixed Assets Schedule
B4: Fiscal Year | C4: 2020 | D4: =C4+1 -> 2021 | E4: =D4+1 -> 2022 | F4: =E4+1 -> 2023 | G4: =F4+1 -> 2024 | H4: =G4+1 -> 2025 | I4: =H4+1 -> 2026 | J4: =I4+1 -> 2027 | K4: 2028 | L4: 2029 | M4: 2030
B5: Beginning PP&E | C5: ='Financials of TCS'!C16-'Financials of TCS'!C24-'Financials of TCS'!C25 -> 18650 | D5: =C8 -> 18370 | E5: =D8 -> 17481 | F5: =E8 -> 15872 | G5: =F8 -> 13950 | H5: =G8 -> 11639 | I5: =H8 -> 10334 | J5: =I8 -> 9379.2586 | K5: =J8 -> 8512.7243 | ... M5: =L8 -> 7012.4322
B6: D&A | C6: 3529 | D6: =FCFF!C10 -> 4065 | E6: =FCFF!D10 -> 4604 | F6: =FCFF!E10 -> 5022 | G6: =FCFF!F10 -> 4985 | H6: =FCFF!G10 -> 5242 | I6: =I5*I12 -> 3096.7814 | J6: =J5*J12 -> 2810.6748 | K6: =K5*K12 -> 2551.0012 | L6: =L5*L12 -> 2315.3184 | M6: =M5*M12 -> 2101.4099
B7: CapEx | C7: =2538+519+192 -> 3249 | D7: =FCFF!C15 -> 3176 | E7: =FCFF!D15 -> 2995 | F7: =FCFF!E15 -> 3100 | G7: =FCFF!F15 -> 2674 | H7: =FCFF!G15 -> 3937 | I7: =I5*I13 -> 2142.0401 | J7: =J5*J13 -> 1944.1405 | K7: =K5*K13 -> 1764.5245 | L7: =L5*L13 -> 1601.503 | M7: =M5*M13 -> 1453.5428
B8: Ending PP&E | C8: =C5-C6+C7 -> 18370 | D8: =D5-D6+D7 -> 17481 | E8: =E5-E6+E7 -> 15872 | F8: =F5-F6+F7 -> 13950 | G8: =G5-G6+G7 -> 11639 | H8: =H5-H6+H7 -> 10334 | I8: =I5-I6+I7 -> 9379.2586 | J8: =J5-J6+J7 -> 8512.7243 | ... M8: =M5-M6+M7 -> 6364.5651
B10: Assumptions
B11: Fiscal Year
B12: D&A as a % of Beginning PP&E | C12: =C6/C5 -> 0.18922252 | D12: =D6/D5 -> 0.2212847 | E12: =E6/E5 -> 0.26337166 | F12: =F6/F5 -> 0.31640625 | G12: =G6/G5 -> 0.35734767 | H12: =H6/H5 -> 0.45038234 | I12: =AVERAGE(C12:H12) -> 0.29966919 | J12: =I12 -> 0.29966919 | K12: =J12 -> 0.29966919 | L12: =K12 -> 0.29966919 | M12: =L12 -> 0.29966919
B13: CapEx as a % of Beginning PP&E | C13: =C7/C5 -> 0.17420912 | D13: =D7/D5 -> 0.17289058 | E13: =E7/E5 -> 0.17132887 | F13: =F7/F5 -> 0.1953125 | G13: =G7/G5 -> 0.19168459 | H13: =H7/H5 -> 0.3382593 | I13: =AVERAGE(C13:H13) -> 0.20728083 | J13: =I13 -> 0.20728083 | K13: =J13 -> 0.20728083 | L13: =K13 -> 0.20728083 | M13: =L13 -> 0.20728083
P144: ='Financials of TCS'!D16-'Financials of TCS'!D24-'Financials of TCS'!D25 -> 18361 | Q144: ='Financials of TCS'!E16-'Financials of TCS'!E24-'Financials of TCS'!E25 -> 17693 | R144: ='Financials of TCS'!F16-'Financials of TCS'!F24-'Financials of TCS'!F25 -> 16639 | S144: ='Financials of TCS'!G16-'Financials of TCS'!G24-'Financials of TCS'!G25 -> 15641 | T144: ='Financials of TCS'!H16-'Financials of TCS'!H24-'Financials of TCS'!H25 -> 18059

Sheet Net Working Capital
C3: Net Working Capital (in Rs. Cr)
C4: Fiscal Year | D4: 2020 | E4: =D4+1 -> 2021 | F4: =E4+1 -> 2022 | G4: =F4+1 -> 2023 | H4: =G4+1 -> 2024 | I4: =H4+1 -> 2025 | J4: =I4+1 -> 2026 | K4: =J4+1 -> 2027 | L4: =K4+1 -> 2028 | ... N4: =M4+1 -> 2030
C5: Accounts Receivables | D5: ='Financials of TCS'!C32 -> 30532 | E5: ='Financials of TCS'!D32 -> 30079 | F5: ='Financials of TCS'!E32 -> 41810 | G5: ='Financials of TCS'!F32 -> 49954 | H5: ='Financials of TCS'!G32 -> 53577 | I5: ='Financials of TCS'!H32 -> 59046 | J5: =J22*J18/360 -> 58543.65 | K5: =K22*K18/360 -> 62641.705 | L5: =L22*L18/360 -> 67339.833 | M5: =M22*M18/360 -> 72727.02 | N5: =N22*N18/360 -> 78545.181
C6: Other Receivables( Intrest Receivable) | D6: 744 | E6: 615 | F6: 648 | G6: 720 | H6: 764 | I6: 888 | J6: =J24*J18/360 -> 922.80167 | K6: =K24*K18/360 -> 987.39778 | L6: =L24*L18/360 -> 1061.4526 | M6: =M24*M18/360 -> 1146.3688 | N6: =N24*N18/360 -> 1238.0783
C7: Other Current Assets | D7: 8206 | E7: 11236 | F7: =10151-F8 -> 7157 | G7: =9707-G8 -> 8213 | H7: =12267-H8 -> 10212 | I7: =14784-I8 -> 12401 | J7: =J18*J26 -> 12679.752 | K7: =K18*K26 -> 12298.313 | L7: =L18*L26 -> 13530.022 | M7: =M18*M26 -> 15073.842 | N7: =N18*N26 -> 16442.573
C8: Prepaid Exp. | D8: 389 | E8: 621 | F8: 2994 | G8: 1494 | H8: 2055 | I8: 2383 | J8: =J29*J20 -> 2707.8289 | K8: =K29*K20 -> 2897.3769 | L8: =L29*L20 -> 3114.6801 | M8: =M29*M20 -> 3363.8546 | N8: =N29*N20 -> 3632.9629
C9: Current Assets | D9: =D5+D7+D8+D6 -> 39871 | E9: =E5+E7+E8+E6 -> 42551 | F9: =F5+F7+F8+F6 -> 52609 | G9: =G5+G7+G8+G6 -> 60381 | H9: =H5+H7+H8+H6 -> 66608 | I9: =I5+I7+I8+I6 -> 74718 | J9: =J5+J6+J7+J8 -> 74854.032 | K9: =K5+K6+K7+K8 -> 78824.793 | L9: =L5+L6+L7+L8 -> 85045.988 | M9: =M5+M6+M7+M8 -> 92311.085 | N9: =N5+N6+N7+N8 -> 99858.795
C10: Accounts Payable | D10: 6740 | E10: 7860 | F10: 2079 | G10: 3759 | H10: 9981 | I10: 13909 | J10: =J23*J19/360 -> 9253.5578 | K10: =K23*K19/360 -> 9901.3069 | L10: =L23*L19/360 -> 10643.905 | M10: =M23*M19/360 -> 11495.417 | N10: =N23*N19/360 -> 12415.051
C11: Accrued Expenses | D11: 3907 | E11: 4482 | F11: 5966 | G11: 6756 | H11: 5760 | I11: 5456 | J11: =J30*J20 -> 6199.7122 | K11: =K30*K20 -> 6633.6921 | L11: =L30*L20 -> 7131.219 | M11: =M30*M20 -> 7701.7165 | N11: =N30*N20 -> 8317.8538
C12: Unearned Revenue | D12: 2915 | E12: 3650 | F12: 3635 | G12: 3843 | H12: 3640 | I12: 4028 | J12: =J28*J18 -> 4289.82 | K12: =K28*K18 -> 4590.1074 | L12: =L28*L18 -> 4934.3655 | M12: =M28*M18 -> 5329.1147 | N12: =N28*N18 -> 5755.4439
C13: Other Current Liabilities | D13: 3283 | E13: 4068 | F13: 8392 | G13: 4892 | H13: 6524 | I13: 7188 | J13: =J27*J18 -> 7655.22 | K13: =K27*K18 -> 8191.0854 | L13: =L27*L18 -> 8805.4168 | M13: =M27*M18 -> 9509.8501 | N13: =N27*N18 -> 10270.638
C14: Current Liabilities | D14: =D13+D12+D11+D10 -> 16845 | E14: =E13+E12+E11+E10 -> 20060 | F14: =F13+F12+F11+F10 -> 20072 | G14: =G13+G12+G11+G10 -> 19250 | H14: =H13+H12+H11+H10 -> 25905 | I14: =I13+I12+I11+I10 -> 30581 | J14: =J10+J11+J12+J13 -> 27398.31 | K14: =K10+K11+K12+K13 -> 29316.192 | L14: =L10+L11+L12+L13 -> 31514.906 | M14: =M10+M11+M12+M13 -> 34036.099 | N14: =N10+N11+N12+N13 -> 36758.987
C16: Assumptions
C17: Fiscal Year | D17: 2020 | E17: 2021 | F17: 2022 | G17: 2023 | H17: 2024 | I17: 2025 | J17: 2026 | K17: 2027 | L17: 2028 | M17: 2029 | N17: 2030
C18: Revenue | E18: =FCFF!C5 -> 164177 | F18: =FCFF!D5 -> 191754 | G18: =FCFF!E5 -> 225458 | H18: =FCFF!F5 -> 240893 | I18: =FCFF!G5 -> 255324 | J18: =FCFF!H5 -> 271920.06 | K18: =FCFF!I5 -> 290954.46 | L18: =FCFF!J5 -> 312776.05 | ... N18: =FCFF!L5 -> 364821.98
C19: COGS | E19: =FCFF!C6 -> 99986.35 | F19: =FCFF!D6 -> 116505.48 | G19: =FCFF!E6 -> 139607.16 | H19: =FCFF!F6 -> 151873.42 | I19: =FCFF!G6 -> 165366.96 | J19: =FCFF!H6 -> 169348.78 | K19: =FCFF!I6 -> 181203.2 | L19: =FCFF!J6 -> 194793.44 | ... N19: =FCFF!L6 -> 227207.06
C20: Operating Expense | E20: =FCFF!C8 -> 19522.8 | F20: =FCFF!D8 -> 17644.65 | G20: =FCFF!E8 -> 22191.52 | H20: =FCFF!F8 -> 26591.84 | I20: =FCFF!G8 -> 24723.58 | J20: =FCFF!H8 -> 28093.673 | K20: =FCFF!I8 -> 30060.23 | L20: =FCFF!J8 -> 32314.748 | ... N20: =FCFF!L8 -> 37691.922
C22: Days Sales Outstanding (DSO) | E22: =E5/E18*360 -> 65.955889 | F22: =F5/F18*360 -> 78.494321 | G22: =G5/G18*360 -> 79.764036 | H22: =H5/H18*360 -> 80.067582 | I22: =I5/I18*360 -> 83.253278 | J22: =AVERAGE(E22:I22) -> 77.507021 | K22: =J22 -> 77.507021 | L22: =K22 -> 77.507021 | M22: =L22 -> 77.507021 | N22: =M22 -> 77.507021
C23: Days Payable Outstanding (DPO) | E23: =E10/E19*360 -> 28.299863 | F23: =F10/F19*360 -> 6.4240755 | G23: =G10/G19*360 -> 9.6931991 | H23: =H10/H19*360 -> 23.658913 | I23: =I10/I19*360 -> 30.279567 | J23: =AVERAGE(E23:I23) -> 19.671124 | K23: =J23 -> 19.671124 | L23: =K23 -> 19.671124 | M23: =L23 -> 19.671124 | N23: =M23 -> 19.671124
C24: Days Sales Outstanding (DSO) Other Receivables | E24: =E6/E18*360 -> 1.3485446 | F24: =F6/F18*360 -> 1.2165587 | G24: =G6/G18*360 -> 1.1496598 | H24: =H6/H18*360 -> 1.1417517 | I24: =I6/I18*360 -> 1.2520562 | J24: =AVERAGE(E24:I24) -> 1.2217142 | K24: =J24 -> 1.2217142 | L24: =K24 -> 1.2217142 | M24: =L24 -> 1.2217142 | N24: =M24 -> 1.2217142
C26: Other Current Assets as a % of Revenue | E26: =E7/E18 -> 0.068438332 | F26: =F7/F18 -> 0.037323863 | G26: =G7/G18 -> 0.036428071 | H26: =H7/H18 -> 0.042392265 | I26: =I7/I18 -> 0.048569661 | J26: =AVERAGE(E26:I26) -> 0.046630438 | K26: =AVERAGE(F26:J26) -> 0.04226886 | L26: =AVERAGE(G26:K26) -> 0.043257859 | M26: =AVERAGE(H26:L26) -> 0.044623817 | N26: =AVERAGE(I26:M26) -> 0.045070127
C27: Other Current Liabilities as a % of Revenue | E27: =E13/E18 -> 0.024778136 | F27: =F13/F18 -> 0.043764406 | G27: =G13/G18 -> 0.021698055 | H27: =H13/H18 -> 0.027082564 | I27: =I13/I18 -> 0.028152465 | J27: =I27 -> 0.028152465 | K27: =J27 -> 0.028152465 | L27: =K27 -> 0.028152465 | M27: =L27 -> 0.028152465 | N27: =M27 -> 0.028152465
C28: Unearned Revenue, Current | E28: =E12/E18 -> 0.022232103 | F28: =F12/F18 -> 0.01895658 | G28: =G12/G18 -> 0.017045303 | H28: =H12/H18 -> 0.015110443 | I28: =I12/I18 -> 0.015776034 | J28: =I28 -> 0.015776034 | K28: =J28 -> 0.015776034 | L28: =K28 -> 0.015776034 | M28: =L28 -> 0.015776034 | N28: =M28 -> 0.015776034
C29: Prepaid Expense | E29: =E8/E20 -> 0.031808962 | F29: =F8/F20 -> 0.16968316 | G29: =G8/G20 -> 0.067323013 | H29: =H8/H20 -> 0.077279346 | I29: =I8/I20 -> 0.096385718 | J29: =I29 -> 0.096385718 | K29: =J29 -> 0.096385718 | L29: =K29 -> 0.096385718 | M29: =L29 -> 0.096385718 | N29: =M29 -> 0.096385718
C30: Accrued Expenses | E30: =E11/E20 -> 0.22957772 | F30: =F11/F20 -> 0.33811949 | G30: =G11/G20 -> 0.30444062 | H30: =H11/H20 -> 0.2166078 | I30: =I11/I20 -> 0.22068001 | J30: =I30 -> 0.22068001 | K30: =J30 -> 0.22068001 | L30: =K30 -> 0.22068001 | M30: =L30 -> 0.22068001 | N30: =M30 -> 0.22068001

Sheet WACC
B4: Weighted Average Cost of Capital (WACC)
B5: Equity (in Rs. Cr) | C5: 94756
B6: Debt (in Rs. Cr) | C6: ='Financials of TCS'!H8 -> 9392
B8: Cost of Debt | C8: ='Financials of TCS'!Q15/WACC!C6 -> 0.084752981
B9: Tax Rate | C9: 0.3
B10: D/(D+E) | C10: =C6/SUM(C5:C6) -> 0.09017936
B11: After Tax Cost of Debt | C11: =C8*(1-C9) -> 0.059327087
B13: Risk Free Rate (10-Yr Gov Bond Yield) | C13: 0.069
B14: Expected Market Return | C14: =C13+C15 -> 0.1398
B15: Market Risk Premium | C15: 0.0708
B16: Beta | C16: 0.2
B17: E/(D+E) | C17: =C5/SUM(C5:C6) -> 0.90982064
B18: Cost of Equity | C18: =C13+C16*(C15) -> 0.08316 | G18: 1
B20: WACC | C20: =C11*C10+C18*C17 -> 0.081010763

Sheet DCF
B4: Unlevered Free Cash Flow (in Rs. Cr)
B5: Fiscal Year | D5: 2021 | E5: 2022 | F5: 2023 | G5: 2024 | H5: 2025 | I5: 2026E | J5: 2027E | K5: 2028E | L5: 2029E | M5: 2030E
B6: Unlevered Free Cash Flow | D6: =FCFF!C20 -> 30391.85 | E6: =FCFF!D20 -> 30908.87 | F6: =FCFF!E20 -> 37208.32 | G6: =FCFF!F20 -> 44317.74 | H6: =FCFF!G20 -> 40952.46 | I6: =FCFF!H20 -> 47602.596 | J6: =FCFF!I20 -> 52629.908 | K6: =FCFF!J20 -> 54945.801 | ... M6: =FCFF!L20 -> 64298.156
B8: Projection Year | I8: 1 | J8: 2 | K8: 3 | L8: 4 | M8: 5
B9: Present Value of Free Cash Flow | I9: =I6/(1+$C$14)^I8 -> 44035.266 | J9: =J6/(1+$C$14)^J8 -> 45037.324 | K9: =K6/(1+$C$14)^K8 -> 43495.513 | L9: =L6/(1+$C$14)^L8 -> 43288.343 | M9: =M6/(1+$C$14)^M8 -> 43556.044
B11: Implied Share Price Calculation | E11: Sensitivity Table
B12: Sum of PV of FCF | C12: =SUM(I9:M9) -> 219412.49
B13: Growth Rate | C13: 0.03 | G13: Growth Rate
B14: WACC | C14: =WACC!C20 -> 0.081010763 | F14: =C23 -> 2267.0862 | G14: =H14-0.5% -> 0.02 | H14: =I14-0.5% -> 0.025 | I14: 0.03 | J14: =I14+0.5% -> 0.035 | K14: =J14+0.5% -> 0.04
B15: Terminal Value | C15: =M9*(1+C13)/(C14-C13) -> 879475.67 | E15: WACC | F15: =F16-0.5% -> 0.071010763 | G15: 2427.0428 | H15: 2631.2327 | I15: 2885.2119 | J15: 3209.7198 | K15: 3638.8713
B16: PV of Terminal Value | C16: =C15/(1+C14)^5 -> 595763.29 | F16: =F17-0.5% -> 0.076010763 | G16: 2184.4734 | H16: 2345.322 | I16: 2541.1294 | J16: 2784.6822 | K16: 3095.8683
B17: Enterprise Value | C17: =C16+C12 -> 815175.78 | F17: 0.081010763 | G17: 1983.8221 | H17: 2112.8108 | I17: 2267.0862 | J17: 2454.8918 | K17: 2688.4916
B18: (+) Cash | C18: ='Financials of TCS'!H33 -> 15463 | F18: =F17+0.5% -> 0.086010763 | G18: 1815.431 | H18: 1920.4267 | I18: 2044.168 | J18: 2192.1673 | K18: 2372.3327
B19: (-) Debt | C19: 9392 | F19: =F18+0.5% -> 0.091010763 | G19: 1672.3702 | H19: 1758.9267 | I19: 1859.6703 | J19: 1978.4003 | K19: 2120.4059
B20: (-) Minority Interest | C20: 1015
B21: Equity Value | C21: =C17+C18-C19-C20 -> 820231.78
B22: Total Shares Outstanding(Cr.) | C22: 361.8
B23: Implied Share Price | C23: =C21/C22 -> 2267.0862

Sheet Comparable Company Analysis
C3: Multiple | D3: Tata Consultancy Services | E3: Infosys | F3: Wipro | G3: Tech Mahindra | H3: HCL Tech | I3: LTI Mindtree
C4: EV / Revenue | D4: ='Peer Comparison'!C21 -> 5.0824008 | E4: ='Peer Comparison'!D21 -> 3.9129093 | F4: ='Peer Comparison'!E21 -> 11.726331 | G4: ='Peer Comparison'!F21 -> 2.5882219 | H4: =427529.93/51105 -> 8.3657163 | I4: ='Peer Comparison'!H21 -> 3.4205956
C5: EV / EBITDA | D5: ='Peer Comparison'!C19 -> 19.2511 | E5: ='Peer Comparison'!D19 -> 16.756833 | F5: ='Peer Comparison'!E19 -> 17.397317 | G5: ='Peer Comparison'!F19 -> 20.105656 | H5: 22.56 | I5: ='Peer Comparison'!H19 -> 18.042708
C6: EV / EBIT | D6: ='Peer Comparison'!C18 -> 20.107831 | E6: ='Peer Comparison'!D18 -> 16.772698 | F6: ='Peer Comparison'!E18 -> 14.57823 | G6: ='Peer Comparison'!F18 -> 22.987714 | H6: =427529.33/16474 -> 25.951762 | I6: ='Peer Comparison'!G17 -> 29.78674
C7: P / E | D7: ='Peer Comparison'!C17 -> 18.324174 | E7: ='Peer Comparison'!D17 -> 20.571939 | F7: ='Peer Comparison'!E17 -> 18.917636 | G7: ='Peer Comparison'!F17 -> 40.049469 | H7: ='Peer Comparison'!G17 -> 29.78674 | I7: ='Peer Comparison'!H17 -> 27.727742
C8: P / Sales | D8: ='Peer Comparison'!C20 -> 3.4162398 | E8: ='Peer Comparison'!D20 -> 3.17425 | F8: ='Peer Comparison'!E20 -> 8.5211632 | G8: ='Peer Comparison'!F20 -> 2.5966068 | H8: ='Peer Comparison'!G20 -> 3.0746026 | I8: ='Peer Comparison'!H20 -> 3.2037645
C9: EV / FCF | D9: ='Peer Comparison'!C6/46600 -> 27.846758 | E9: ='Peer Comparison'!D6/32030 -> 19.911492 | F9: ='Peer Comparison'!E6/13740 -> 20.102891 | G9: ='Peer Comparison'!F6/5190 -> 26.424798 | H9: =427529.93/21260 -> 20.109592 | I9: =130010.34/3590 -> 36.214579
C13: Multiple | D13: Peer Median | E13: Target Metric | F13: Implied EV / Equity Value | G13: Implied Share Price
C14: EV / Revenue | D14: =MEDIAN(E4:I4) -> 3.9129093 | E14: =FCFF!I5 -> 290954.46 | F14: =D14*E14 -> 1138478.4 | G14: =F14/361.9 -> 3145.837
C15: EV / EBITDA | D15: =MEDIAN(E5:I5) -> 18.042708 | E15: =FCFF!I9 -> 79691.037 | F15: =D15*E15 -> 1437842.1 | G15: =F15/361.9 -> 3973.037
C16: EV / EBIT | D16: =MEDIAN(E6:I6) -> 22.987714 | E16: =FCFF!I11 -> 76880.362 | F16: =D16*E16 -> 1767303.8 | G16: =F16/361.9 -> 4883.4036
C17: P / E | D17: =MEDIAN(E7:I7) -> 27.727742 | E17: =FCFF!I13 -> 53816.254 | F17: =D17*E17 -> 1492203.2 | G17: =F17/361.9 -> 4123.2473
C18: P/ Sales | D18: =MEDIAN(E8:I8) -> 3.17425 | E18: =E14 -> 290954.46 | F18: =D18*E18 -> 923562.19 | G18: =F18/361.9 -> 2551.9817
C19: EV / FCF | D19: =MEDIAN(E9:I9) -> 20.109592 | E19: =FCFF!I20 -> 52629.908 | F19: =D19*E19 -> 1058366 | G19: =F19/361.9 -> 2924.4708
